[2025-05-23T18:53:21.684+0000] {local_task_job_runner.py:123} INFO - ::group::Pre task execution logs
[2025-05-23T18:53:21.712+0000] {taskinstance.py:2614} INFO - Dependencies all met for dep_context=non-requeueable deps ti=<TaskInstance: crypto_etl_pipeline.transform_data manual__2025-05-23T18:53:14.575733+00:00 [queued]>
[2025-05-23T18:53:21.723+0000] {taskinstance.py:2614} INFO - Dependencies all met for dep_context=requeueable deps ti=<TaskInstance: crypto_etl_pipeline.transform_data manual__2025-05-23T18:53:14.575733+00:00 [queued]>
[2025-05-23T18:53:21.723+0000] {taskinstance.py:2867} INFO - Starting attempt 1 of 1
[2025-05-23T18:53:21.739+0000] {taskinstance.py:2890} INFO - Executing <Task(PythonOperator): transform_data> on 2025-05-23 18:53:14.575733+00:00
[2025-05-23T18:53:21.746+0000] {warnings.py:112} WARNING - /home/***/.local/lib/python3.12/site-packages/***/task/task_runner/standard_task_runner.py:70: DeprecationWarning: This process (pid=345) is multi-threaded, use of fork() may lead to deadlocks in the child.
  pid = os.fork()

[2025-05-23T18:53:21.748+0000] {standard_task_runner.py:72} INFO - Started process 347 to run task
[2025-05-23T18:53:21.749+0000] {standard_task_runner.py:104} INFO - Running: ['***', 'tasks', 'run', 'crypto_etl_pipeline', 'transform_data', 'manual__2025-05-23T18:53:14.575733+00:00', '--job-id', '179', '--raw', '--subdir', 'DAGS_FOLDER/crypto_etl_dag.py', '--cfg-path', '/tmp/tmpbu9ypgw4']
[2025-05-23T18:53:21.750+0000] {standard_task_runner.py:105} INFO - Job 179: Subtask transform_data
[2025-05-23T18:53:21.799+0000] {task_command.py:467} INFO - Running <TaskInstance: crypto_etl_pipeline.transform_data manual__2025-05-23T18:53:14.575733+00:00 [running]> on host ede6358c2bd0
[2025-05-23T18:53:21.873+0000] {taskinstance.py:3134} INFO - Exporting env vars: AIRFLOW_CTX_DAG_OWNER='***' AIRFLOW_CTX_DAG_ID='crypto_etl_pipeline' AIRFLOW_CTX_TASK_ID='transform_data' AIRFLOW_CTX_EXECUTION_DATE='2025-05-23T18:53:14.575733+00:00' AIRFLOW_CTX_TRY_NUMBER='1' AIRFLOW_CTX_DAG_RUN_ID='manual__2025-05-23T18:53:14.575733+00:00'
[2025-05-23T18:53:21.874+0000] {logging_mixin.py:190} INFO - Task instance is in running state
[2025-05-23T18:53:21.875+0000] {logging_mixin.py:190} INFO -  Previous state of the Task instance: queued
[2025-05-23T18:53:21.875+0000] {logging_mixin.py:190} INFO - Current task name:transform_data state:running start_date:2025-05-23 18:53:21.713201+00:00
[2025-05-23T18:53:21.875+0000] {logging_mixin.py:190} INFO - Dag name:crypto_etl_pipeline and current dag run status:running
[2025-05-23T18:53:21.876+0000] {taskinstance.py:732} INFO - ::endgroup::
[2025-05-23T18:53:21.878+0000] {taskinstance.py:3313} ERROR - Task failed with exception
Traceback (most recent call last):
  File "/home/airflow/.local/lib/python3.12/site-packages/airflow/models/taskinstance.py", line 768, in _execute_task
    result = _execute_callable(context=context, **execute_callable_kwargs)
             ^^^^^^^^^^^^^^^^^^^^^^^^^^^^^^^^^^^^^^^^^^^^^^^^^^^^^^^^^^^^^
  File "/home/airflow/.local/lib/python3.12/site-packages/airflow/models/taskinstance.py", line 734, in _execute_callable
    return ExecutionCallableRunner(
           ^^^^^^^^^^^^^^^^^^^^^^^^
  File "/home/airflow/.local/lib/python3.12/site-packages/airflow/utils/operator_helpers.py", line 252, in run
    return self.func(*args, **kwargs)
           ^^^^^^^^^^^^^^^^^^^^^^^^^^
  File "/home/airflow/.local/lib/python3.12/site-packages/airflow/models/baseoperator.py", line 424, in wrapper
    return func(self, *args, **kwargs)
           ^^^^^^^^^^^^^^^^^^^^^^^^^^^
  File "/home/airflow/.local/lib/python3.12/site-packages/airflow/operators/python.py", line 238, in execute
    return_value = self.execute_callable()
                   ^^^^^^^^^^^^^^^^^^^^^^^
  File "/home/airflow/.local/lib/python3.12/site-packages/airflow/operators/python.py", line 256, in execute_callable
    return runner.run(*self.op_args, **self.op_kwargs)
           ^^^^^^^^^^^^^^^^^^^^^^^^^^^^^^^^^^^^^^^^^^^
  File "/home/airflow/.local/lib/python3.12/site-packages/airflow/utils/operator_helpers.py", line 252, in run
    return self.func(*args, **kwargs)
           ^^^^^^^^^^^^^^^^^^^^^^^^^^
  File "/opt/airflow/dags/scripts/transform.py", line 4, in transform_crypto_data
    df = pd.read_csv('opt/airflow/data/bronze/crypto_prices_raw.csv')
         ^^^^^^^^^^^^^^^^^^^^^^^^^^^^^^^^^^^^^^^^^^^^^^^^^^^^^^^^^^^^
  File "/home/airflow/.local/lib/python3.12/site-packages/pandas/io/parsers/readers.py", line 948, in read_csv
    return _read(filepath_or_buffer, kwds)
           ^^^^^^^^^^^^^^^^^^^^^^^^^^^^^^^
  File "/home/airflow/.local/lib/python3.12/site-packages/pandas/io/parsers/readers.py", line 611, in _read
    parser = TextFileReader(filepath_or_buffer, **kwds)
             ^^^^^^^^^^^^^^^^^^^^^^^^^^^^^^^^^^^^^^^^^^
  File "/home/airflow/.local/lib/python3.12/site-packages/pandas/io/parsers/readers.py", line 1448, in __init__
    self._engine = self._make_engine(f, self.engine)
                   ^^^^^^^^^^^^^^^^^^^^^^^^^^^^^^^^^
  File "/home/airflow/.local/lib/python3.12/site-packages/pandas/io/parsers/readers.py", line 1705, in _make_engine
    self.handles = get_handle(
                   ^^^^^^^^^^^
  File "/home/airflow/.local/lib/python3.12/site-packages/pandas/io/common.py", line 863, in get_handle
    handle = open(
             ^^^^^
FileNotFoundError: [Errno 2] No such file or directory: 'opt/airflow/data/bronze/crypto_prices_raw.csv'
[2025-05-23T18:53:21.890+0000] {logging_mixin.py:190} INFO - Task instance in failure state
[2025-05-23T18:53:21.891+0000] {logging_mixin.py:190} INFO - Task start:2025-05-23 18:53:21.713201+00:00 end:2025-05-23 18:53:21.890394+00:00 duration:0.177193
[2025-05-23T18:53:21.891+0000] {logging_mixin.py:190} INFO - Task:<Task(PythonOperator): transform_data> dag:<DAG: crypto_etl_pipeline> dagrun:<DagRun crypto_etl_pipeline @ 2025-05-23 18:53:14.575733+00:00: manual__2025-05-23T18:53:14.575733+00:00, state:running, queued_at: 2025-05-23 18:53:14.584186+00:00. externally triggered: True>
[2025-05-23T18:53:21.892+0000] {logging_mixin.py:190} INFO - Failure caused by [Errno 2] No such file or directory: 'opt/***/data/bronze/crypto_prices_raw.csv'
[2025-05-23T18:53:21.892+0000] {taskinstance.py:1226} INFO - Marking task as FAILED. dag_id=crypto_etl_pipeline, task_id=transform_data, run_id=manual__2025-05-23T18:53:14.575733+00:00, execution_date=20250523T185314, start_date=20250523T185321, end_date=20250523T185321
[2025-05-23T18:53:22.077+0000] {taskinstance.py:341} INFO - ::group::Post task execution logs
[2025-05-23T18:53:22.077+0000] {standard_task_runner.py:124} ERROR - Failed to execute job 179 for task transform_data ([Errno 2] No such file or directory: 'opt/airflow/data/bronze/crypto_prices_raw.csv'; 347)
Traceback (most recent call last):
  File "/home/airflow/.local/lib/python3.12/site-packages/airflow/task/task_runner/standard_task_runner.py", line 117, in _start_by_fork
    ret = args.func(args, dag=self.dag)
          ^^^^^^^^^^^^^^^^^^^^^^^^^^^^^
  File "/home/airflow/.local/lib/python3.12/site-packages/airflow/cli/cli_config.py", line 49, in command
    return func(*args, **kwargs)
           ^^^^^^^^^^^^^^^^^^^^^
  File "/home/airflow/.local/lib/python3.12/site-packages/airflow/utils/cli.py", line 116, in wrapper
    return f(*args, **kwargs)
           ^^^^^^^^^^^^^^^^^^
  File "/home/airflow/.local/lib/python3.12/site-packages/airflow/cli/commands/task_command.py", line 483, in task_run
    task_return_code = _run_task_by_selected_method(args, _dag, ti)
                       ^^^^^^^^^^^^^^^^^^^^^^^^^^^^^^^^^^^^^^^^^^^^
  File "/home/airflow/.local/lib/python3.12/site-packages/airflow/cli/commands/task_command.py", line 256, in _run_task_by_selected_method
    return _run_raw_task(args, ti)
           ^^^^^^^^^^^^^^^^^^^^^^^
  File "/home/airflow/.local/lib/python3.12/site-packages/airflow/cli/commands/task_command.py", line 341, in _run_raw_task
    return ti._run_raw_task(
           ^^^^^^^^^^^^^^^^^
  File "/home/airflow/.local/lib/python3.12/site-packages/airflow/utils/session.py", line 97, in wrapper
    return func(*args, session=session, **kwargs)
           ^^^^^^^^^^^^^^^^^^^^^^^^^^^^^^^^^^^^^^
  File "/home/airflow/.local/lib/python3.12/site-packages/airflow/models/taskinstance.py", line 3006, in _run_raw_task
    return _run_raw_task(
           ^^^^^^^^^^^^^^
  File "/home/airflow/.local/lib/python3.12/site-packages/airflow/models/taskinstance.py", line 274, in _run_raw_task
    TaskInstance._execute_task_with_callbacks(
  File "/home/airflow/.local/lib/python3.12/site-packages/airflow/models/taskinstance.py", line 3161, in _execute_task_with_callbacks
    result = self._execute_task(context, task_orig)
             ^^^^^^^^^^^^^^^^^^^^^^^^^^^^^^^^^^^^^^
  File "/home/airflow/.local/lib/python3.12/site-packages/airflow/models/taskinstance.py", line 3185, in _execute_task
    return _execute_task(self, context, task_orig)
           ^^^^^^^^^^^^^^^^^^^^^^^^^^^^^^^^^^^^^^^
  File "/home/airflow/.local/lib/python3.12/site-packages/airflow/models/taskinstance.py", line 768, in _execute_task
    result = _execute_callable(context=context, **execute_callable_kwargs)
             ^^^^^^^^^^^^^^^^^^^^^^^^^^^^^^^^^^^^^^^^^^^^^^^^^^^^^^^^^^^^^
  File "/home/airflow/.local/lib/python3.12/site-packages/airflow/models/taskinstance.py", line 734, in _execute_callable
    return ExecutionCallableRunner(
           ^^^^^^^^^^^^^^^^^^^^^^^^
  File "/home/airflow/.local/lib/python3.12/site-packages/airflow/utils/operator_helpers.py", line 252, in run
    return self.func(*args, **kwargs)
           ^^^^^^^^^^^^^^^^^^^^^^^^^^
  File "/home/airflow/.local/lib/python3.12/site-packages/airflow/models/baseoperator.py", line 424, in wrapper
    return func(self, *args, **kwargs)
           ^^^^^^^^^^^^^^^^^^^^^^^^^^^
  File "/home/airflow/.local/lib/python3.12/site-packages/airflow/operators/python.py", line 238, in execute
    return_value = self.execute_callable()
                   ^^^^^^^^^^^^^^^^^^^^^^^
  File "/home/airflow/.local/lib/python3.12/site-packages/airflow/operators/python.py", line 256, in execute_callable
    return runner.run(*self.op_args, **self.op_kwargs)
           ^^^^^^^^^^^^^^^^^^^^^^^^^^^^^^^^^^^^^^^^^^^
  File "/home/airflow/.local/lib/python3.12/site-packages/airflow/utils/operator_helpers.py", line 252, in run
    return self.func(*args, **kwargs)
           ^^^^^^^^^^^^^^^^^^^^^^^^^^
  File "/opt/airflow/dags/scripts/transform.py", line 4, in transform_crypto_data
    df = pd.read_csv('opt/airflow/data/bronze/crypto_prices_raw.csv')
         ^^^^^^^^^^^^^^^^^^^^^^^^^^^^^^^^^^^^^^^^^^^^^^^^^^^^^^^^^^^^
  File "/home/airflow/.local/lib/python3.12/site-packages/pandas/io/parsers/readers.py", line 948, in read_csv
    return _read(filepath_or_buffer, kwds)
           ^^^^^^^^^^^^^^^^^^^^^^^^^^^^^^^
  File "/home/airflow/.local/lib/python3.12/site-packages/pandas/io/parsers/readers.py", line 611, in _read
    parser = TextFileReader(filepath_or_buffer, **kwds)
             ^^^^^^^^^^^^^^^^^^^^^^^^^^^^^^^^^^^^^^^^^^
  File "/home/airflow/.local/lib/python3.12/site-packages/pandas/io/parsers/readers.py", line 1448, in __init__
    self._engine = self._make_engine(f, self.engine)
                   ^^^^^^^^^^^^^^^^^^^^^^^^^^^^^^^^^
  File "/home/airflow/.local/lib/python3.12/site-packages/pandas/io/parsers/readers.py", line 1705, in _make_engine
    self.handles = get_handle(
                   ^^^^^^^^^^^
  File "/home/airflow/.local/lib/python3.12/site-packages/pandas/io/common.py", line 863, in get_handle
    handle = open(
             ^^^^^
FileNotFoundError: [Errno 2] No such file or directory: 'opt/airflow/data/bronze/crypto_prices_raw.csv'
[2025-05-23T18:53:22.124+0000] {local_task_job_runner.py:266} INFO - Task exited with return code 1
[2025-05-23T18:53:22.143+0000] {taskinstance.py:3901} INFO - 0 downstream tasks scheduled from follow-on schedule check
[2025-05-23T18:53:22.147+0000] {local_task_job_runner.py:245} INFO - ::endgroup::
