[2025-05-23T19:03:41.787+0000] {local_task_job_runner.py:123} INFO - ::group::Pre task execution logs
[2025-05-23T19:03:41.812+0000] {taskinstance.py:2614} INFO - Dependencies all met for dep_context=non-requeueable deps ti=<TaskInstance: crypto_etl_pipeline.load_data manual__2025-05-23T19:03:32.175131+00:00 [queued]>
[2025-05-23T19:03:41.823+0000] {taskinstance.py:2614} INFO - Dependencies all met for dep_context=requeueable deps ti=<TaskInstance: crypto_etl_pipeline.load_data manual__2025-05-23T19:03:32.175131+00:00 [queued]>
[2025-05-23T19:03:41.823+0000] {taskinstance.py:2867} INFO - Starting attempt 1 of 1
[2025-05-23T19:03:41.841+0000] {taskinstance.py:2890} INFO - Executing <Task(PythonOperator): load_data> on 2025-05-23 19:03:32.175131+00:00
[2025-05-23T19:03:41.848+0000] {warnings.py:112} WARNING - /home/***/.local/lib/python3.12/site-packages/***/task/task_runner/standard_task_runner.py:70: DeprecationWarning: This process (pid=527) is multi-threaded, use of fork() may lead to deadlocks in the child.
  pid = os.fork()

[2025-05-23T19:03:41.850+0000] {standard_task_runner.py:72} INFO - Started process 529 to run task
[2025-05-23T19:03:41.851+0000] {standard_task_runner.py:104} INFO - Running: ['***', 'tasks', 'run', 'crypto_etl_pipeline', 'load_data', 'manual__2025-05-23T19:03:32.175131+00:00', '--job-id', '191', '--raw', '--subdir', 'DAGS_FOLDER/crypto_etl_dag.py', '--cfg-path', '/tmp/tmp_l2yu748']
[2025-05-23T19:03:41.852+0000] {standard_task_runner.py:105} INFO - Job 191: Subtask load_data
[2025-05-23T19:03:41.902+0000] {task_command.py:467} INFO - Running <TaskInstance: crypto_etl_pipeline.load_data manual__2025-05-23T19:03:32.175131+00:00 [running]> on host ede6358c2bd0
[2025-05-23T19:03:41.980+0000] {taskinstance.py:3134} INFO - Exporting env vars: AIRFLOW_CTX_DAG_OWNER='***' AIRFLOW_CTX_DAG_ID='crypto_etl_pipeline' AIRFLOW_CTX_TASK_ID='load_data' AIRFLOW_CTX_EXECUTION_DATE='2025-05-23T19:03:32.175131+00:00' AIRFLOW_CTX_TRY_NUMBER='1' AIRFLOW_CTX_DAG_RUN_ID='manual__2025-05-23T19:03:32.175131+00:00'
[2025-05-23T19:03:41.981+0000] {logging_mixin.py:190} INFO - Task instance is in running state
[2025-05-23T19:03:41.982+0000] {logging_mixin.py:190} INFO -  Previous state of the Task instance: queued
[2025-05-23T19:03:41.982+0000] {logging_mixin.py:190} INFO - Current task name:load_data state:running start_date:2025-05-23 19:03:41.813298+00:00
[2025-05-23T19:03:41.982+0000] {logging_mixin.py:190} INFO - Dag name:crypto_etl_pipeline and current dag run status:running
[2025-05-23T19:03:41.983+0000] {taskinstance.py:732} INFO - ::endgroup::
[2025-05-23T19:03:41.991+0000] {taskinstance.py:3313} ERROR - Task failed with exception
Traceback (most recent call last):
  File "/home/airflow/.local/lib/python3.12/site-packages/airflow/models/taskinstance.py", line 768, in _execute_task
    result = _execute_callable(context=context, **execute_callable_kwargs)
             ^^^^^^^^^^^^^^^^^^^^^^^^^^^^^^^^^^^^^^^^^^^^^^^^^^^^^^^^^^^^^
  File "/home/airflow/.local/lib/python3.12/site-packages/airflow/models/taskinstance.py", line 734, in _execute_callable
    return ExecutionCallableRunner(
           ^^^^^^^^^^^^^^^^^^^^^^^^
  File "/home/airflow/.local/lib/python3.12/site-packages/airflow/utils/operator_helpers.py", line 252, in run
    return self.func(*args, **kwargs)
           ^^^^^^^^^^^^^^^^^^^^^^^^^^
  File "/home/airflow/.local/lib/python3.12/site-packages/airflow/models/baseoperator.py", line 424, in wrapper
    return func(self, *args, **kwargs)
           ^^^^^^^^^^^^^^^^^^^^^^^^^^^
  File "/home/airflow/.local/lib/python3.12/site-packages/airflow/operators/python.py", line 238, in execute
    return_value = self.execute_callable()
                   ^^^^^^^^^^^^^^^^^^^^^^^
  File "/home/airflow/.local/lib/python3.12/site-packages/airflow/operators/python.py", line 256, in execute_callable
    return runner.run(*self.op_args, **self.op_kwargs)
           ^^^^^^^^^^^^^^^^^^^^^^^^^^^^^^^^^^^^^^^^^^^
  File "/home/airflow/.local/lib/python3.12/site-packages/airflow/utils/operator_helpers.py", line 252, in run
    return self.func(*args, **kwargs)
           ^^^^^^^^^^^^^^^^^^^^^^^^^^
  File "/opt/airflow/dags/scripts/load.py", line 8, in load_to_sqlite
    conn = sqlite3.connect('/opt/airflow/db/crypto.db')                   # conecta ao banco SQLite
           ^^^^^^^^^^^^^^^^^^^^^^^^^^^^^^^^^^^^^^^^^^^^
sqlite3.OperationalError: unable to open database file
[2025-05-23T19:03:42.002+0000] {logging_mixin.py:190} INFO - Task instance in failure state
[2025-05-23T19:03:42.002+0000] {logging_mixin.py:190} INFO - Task start:2025-05-23 19:03:41.813298+00:00 end:2025-05-23 19:03:42.001904+00:00 duration:0.188606
[2025-05-23T19:03:42.003+0000] {logging_mixin.py:190} INFO - Task:<Task(PythonOperator): load_data> dag:<DAG: crypto_etl_pipeline> dagrun:<DagRun crypto_etl_pipeline @ 2025-05-23 19:03:32.175131+00:00: manual__2025-05-23T19:03:32.175131+00:00, state:running, queued_at: 2025-05-23 19:03:32.192473+00:00. externally triggered: True>
[2025-05-23T19:03:42.003+0000] {logging_mixin.py:190} INFO - Failure caused by unable to open database file
[2025-05-23T19:03:42.003+0000] {taskinstance.py:1226} INFO - Marking task as FAILED. dag_id=crypto_etl_pipeline, task_id=load_data, run_id=manual__2025-05-23T19:03:32.175131+00:00, execution_date=20250523T190332, start_date=20250523T190341, end_date=20250523T190342
[2025-05-23T19:03:42.199+0000] {taskinstance.py:341} INFO - ::group::Post task execution logs
[2025-05-23T19:03:42.200+0000] {standard_task_runner.py:124} ERROR - Failed to execute job 191 for task load_data (unable to open database file; 529)
Traceback (most recent call last):
  File "/home/airflow/.local/lib/python3.12/site-packages/airflow/task/task_runner/standard_task_runner.py", line 117, in _start_by_fork
    ret = args.func(args, dag=self.dag)
          ^^^^^^^^^^^^^^^^^^^^^^^^^^^^^
  File "/home/airflow/.local/lib/python3.12/site-packages/airflow/cli/cli_config.py", line 49, in command
    return func(*args, **kwargs)
           ^^^^^^^^^^^^^^^^^^^^^
  File "/home/airflow/.local/lib/python3.12/site-packages/airflow/utils/cli.py", line 116, in wrapper
    return f(*args, **kwargs)
           ^^^^^^^^^^^^^^^^^^
  File "/home/airflow/.local/lib/python3.12/site-packages/airflow/cli/commands/task_command.py", line 483, in task_run
    task_return_code = _run_task_by_selected_method(args, _dag, ti)
                       ^^^^^^^^^^^^^^^^^^^^^^^^^^^^^^^^^^^^^^^^^^^^
  File "/home/airflow/.local/lib/python3.12/site-packages/airflow/cli/commands/task_command.py", line 256, in _run_task_by_selected_method
    return _run_raw_task(args, ti)
           ^^^^^^^^^^^^^^^^^^^^^^^
  File "/home/airflow/.local/lib/python3.12/site-packages/airflow/cli/commands/task_command.py", line 341, in _run_raw_task
    return ti._run_raw_task(
           ^^^^^^^^^^^^^^^^^
  File "/home/airflow/.local/lib/python3.12/site-packages/airflow/utils/session.py", line 97, in wrapper
    return func(*args, session=session, **kwargs)
           ^^^^^^^^^^^^^^^^^^^^^^^^^^^^^^^^^^^^^^
  File "/home/airflow/.local/lib/python3.12/site-packages/airflow/models/taskinstance.py", line 3006, in _run_raw_task
    return _run_raw_task(
           ^^^^^^^^^^^^^^
  File "/home/airflow/.local/lib/python3.12/site-packages/airflow/models/taskinstance.py", line 274, in _run_raw_task
    TaskInstance._execute_task_with_callbacks(
  File "/home/airflow/.local/lib/python3.12/site-packages/airflow/models/taskinstance.py", line 3161, in _execute_task_with_callbacks
    result = self._execute_task(context, task_orig)
             ^^^^^^^^^^^^^^^^^^^^^^^^^^^^^^^^^^^^^^
  File "/home/airflow/.local/lib/python3.12/site-packages/airflow/models/taskinstance.py", line 3185, in _execute_task
    return _execute_task(self, context, task_orig)
           ^^^^^^^^^^^^^^^^^^^^^^^^^^^^^^^^^^^^^^^
  File "/home/airflow/.local/lib/python3.12/site-packages/airflow/models/taskinstance.py", line 768, in _execute_task
    result = _execute_callable(context=context, **execute_callable_kwargs)
             ^^^^^^^^^^^^^^^^^^^^^^^^^^^^^^^^^^^^^^^^^^^^^^^^^^^^^^^^^^^^^
  File "/home/airflow/.local/lib/python3.12/site-packages/airflow/models/taskinstance.py", line 734, in _execute_callable
    return ExecutionCallableRunner(
           ^^^^^^^^^^^^^^^^^^^^^^^^
  File "/home/airflow/.local/lib/python3.12/site-packages/airflow/utils/operator_helpers.py", line 252, in run
    return self.func(*args, **kwargs)
           ^^^^^^^^^^^^^^^^^^^^^^^^^^
  File "/home/airflow/.local/lib/python3.12/site-packages/airflow/models/baseoperator.py", line 424, in wrapper
    return func(self, *args, **kwargs)
           ^^^^^^^^^^^^^^^^^^^^^^^^^^^
  File "/home/airflow/.local/lib/python3.12/site-packages/airflow/operators/python.py", line 238, in execute
    return_value = self.execute_callable()
                   ^^^^^^^^^^^^^^^^^^^^^^^
  File "/home/airflow/.local/lib/python3.12/site-packages/airflow/operators/python.py", line 256, in execute_callable
    return runner.run(*self.op_args, **self.op_kwargs)
           ^^^^^^^^^^^^^^^^^^^^^^^^^^^^^^^^^^^^^^^^^^^
  File "/home/airflow/.local/lib/python3.12/site-packages/airflow/utils/operator_helpers.py", line 252, in run
    return self.func(*args, **kwargs)
           ^^^^^^^^^^^^^^^^^^^^^^^^^^
  File "/opt/airflow/dags/scripts/load.py", line 8, in load_to_sqlite
    conn = sqlite3.connect('/opt/airflow/db/crypto.db')                   # conecta ao banco SQLite
           ^^^^^^^^^^^^^^^^^^^^^^^^^^^^^^^^^^^^^^^^^^^^
sqlite3.OperationalError: unable to open database file
[2025-05-23T19:03:42.225+0000] {local_task_job_runner.py:266} INFO - Task exited with return code 1
[2025-05-23T19:03:42.239+0000] {taskinstance.py:3901} INFO - 0 downstream tasks scheduled from follow-on schedule check
[2025-05-23T19:03:42.241+0000] {local_task_job_runner.py:245} INFO - ::endgroup::
